2021-10-05 16:35:44 WARNING (SyncWorker_1) [homeassistant.loader] We found a custom integration hacs which has not been tested by Home Assistant. This component might cause stability problems, be sure to disable it if you experience issues with Home Assistant
2021-10-05 16:35:44 WARNING (SyncWorker_0) [homeassistant.loader] We found a custom integration hadockermon which has not been tested by Home Assistant. This component might cause stability problems, be sure to disable it if you experience issues with Home Assistant
2021-10-05 16:35:44 ERROR (SyncWorker_0) [homeassistant.loader] The custom integration 'hadockermon' does not have a valid version key (None) in the manifest file and was blocked from loading. See https://developers.home-assistant.io/blog/2021/01/29/custom-integration-changes#versions for more details
2021-10-05 16:35:44 WARNING (SyncWorker_2) [homeassistant.loader] We found a custom integration nodered which has not been tested by Home Assistant. This component might cause stability problems, be sure to disable it if you experience issues with Home Assistant
2021-10-05 16:35:44 WARNING (SyncWorker_3) [homeassistant.loader] We found a custom integration ical which has not been tested by Home Assistant. This component might cause stability problems, be sure to disable it if you experience issues with Home Assistant
2021-10-05 16:35:44 WARNING (SyncWorker_4) [homeassistant.loader] We found a custom integration alexa_media which has not been tested by Home Assistant. This component might cause stability problems, be sure to disable it if you experience issues with Home Assistant
2021-10-05 16:35:47 ERROR (SyncWorker_3) [homeassistant.components.influxdb] InfluxDB bucket is not accessible due to '(401)
Reason: Unauthorized
HTTP response headers: HTTPHeaderDict({'Content-Type': 'application/json; charset=utf-8', 'X-Platform-Error-Code': 'unauthorized', 'Date': 'Tue, 05 Oct 2021 21:35:47 GMT', 'Content-Length': '55'})
HTTP response body: {"code":"unauthorized","message":"unauthorized access"}
'. Please check that the bucket, org and token are correct and that the token has the correct permissions set. Retrying in 60 seconds.
2021-10-05 16:35:47 WARNING (MainThread) [homeassistant.components.updater] Analytics reporting with the option 'include_used_components' is deprecated and you should remove that from your configuration. The analytics part of this integration has moved to the new 'analytics' integration
2021-10-05 16:35:47 WARNING (MainThread) [homeassistant.components.updater] Analytics reporting with the option 'reporting' is deprecated and you should remove that from your configuration. The analytics part of this integration has moved to the new 'analytics' integration
2021-10-05 16:35:48 WARNING (MainThread) [homeassistant.components.uptime.sensor] The 'unit_of_measurement' option near /config/configuration/sensor.yaml:172 is deprecated, please remove it from your configuration
2021-10-05 16:35:49 ERROR (MainThread) [snitun.client.client_peer] Challenge/Response error with SniTun server
2021-10-05 16:35:49 ERROR (MainThread) [hass_nabucasa.remote] Connection problem to snitun server
2021-10-05 16:35:49 ERROR (MainThread) [homeassistant.components.weather] Error adding entities for domain weather with platform nws
Traceback (most recent call last):
  File "/usr/src/homeassistant/homeassistant/helpers/entity_platform.py", line 382, in async_add_entities
    await asyncio.gather(*tasks)
  File "/usr/src/homeassistant/homeassistant/helpers/entity_platform.py", line 587, in _async_add_entity
    await entity.add_to_platform_finish()
  File "/usr/src/homeassistant/homeassistant/helpers/entity.py", line 697, in add_to_platform_finish
    await self.async_added_to_hass()
  File "/usr/src/homeassistant/homeassistant/components/nws/weather.py", line 124, in async_added_to_hass
    self._update_callback()
  File "/usr/src/homeassistant/homeassistant/components/nws/weather.py", line 129, in _update_callback
    self.observation = self.nws.observation
  File "/usr/local/lib/python3.9/site-packages/pynws/simple_nws.py", line 261, in observation
    data[obs] = unit_conversion[obs_item[1]](obs_item[0])
KeyError: 'wmoUnit:degC'
2021-10-05 16:35:49 ERROR (MainThread) [homeassistant.components.weather] Error while setting up nws platform for weather
Traceback (most recent call last):
  File "/usr/src/homeassistant/homeassistant/helpers/entity_platform.py", line 257, in _async_setup_platform
    await asyncio.gather(*pending)
  File "/usr/src/homeassistant/homeassistant/helpers/entity_platform.py", line 382, in async_add_entities
    await asyncio.gather(*tasks)
  File "/usr/src/homeassistant/homeassistant/helpers/entity_platform.py", line 587, in _async_add_entity
    await entity.add_to_platform_finish()
  File "/usr/src/homeassistant/homeassistant/helpers/entity.py", line 697, in add_to_platform_finish
    await self.async_added_to_hass()
  File "/usr/src/homeassistant/homeassistant/components/nws/weather.py", line 124, in async_added_to_hass
    self._update_callback()
  File "/usr/src/homeassistant/homeassistant/components/nws/weather.py", line 129, in _update_callback
    self.observation = self.nws.observation
  File "/usr/local/lib/python3.9/site-packages/pynws/simple_nws.py", line 261, in observation
    data[obs] = unit_conversion[obs_item[1]](obs_item[0])
KeyError: 'wmoUnit:degC'
2021-10-05 16:36:04 WARNING (MainThread) [homeassistant.components.webhook] Received message for unregistered webhook 51a813b6c4d87fca67138b5853aafcf7e28fa92cc2cc5ad4eb12d64debdc6da8 from cloud
2021-10-05 16:36:05 ERROR (MainThread) [homeassistant.components.websocket_api.http.connection] [23077627082208] Received invalid command: mobile_app/push_notification_channel
2021-10-05 16:36:19 WARNING (MainThread) [homeassistant.components.esphome] Can't connect to ESPHome API for sonoffbasic_plug_01 (10.0.0.157): Timeout while connecting to ('10.0.0.157', 6053)
2021-10-05 16:36:19 WARNING (MainThread) [homeassistant.components.esphome] Can't connect to ESPHome API for plant_monitor_1 (10.0.0.159): Timeout while connecting to ('10.0.0.159', 6053)
2021-10-05 16:36:25 WARNING (MainThread) [homeassistant.components.webhook] Received message for unregistered webhook 51a813b6c4d87fca67138b5853aafcf7e28fa92cc2cc5ad4eb12d64debdc6da8 from cloud
2021-10-05 16:36:39 ERROR (MainThread) [homeassistant.components.websocket_api.http.connection] [23077636193920] Received invalid command: mobile_app/push_notification_channel
2021-10-05 16:36:46 WARNING (MainThread) [homeassistant.bootstrap] Waiting on integrations to complete setup: notify, notify.alexa_media
2021-10-05 16:36:47 ERROR (SyncWorker_0) [homeassistant.components.influxdb] InfluxDB bucket is not accessible due to '(401)
Reason: Unauthorized
HTTP response headers: HTTPHeaderDict({'Content-Type': 'application/json; charset=utf-8', 'X-Platform-Error-Code': 'unauthorized', 'Date': 'Tue, 05 Oct 2021 21:36:47 GMT', 'Content-Length': '55'})
HTTP response body: {"code":"unauthorized","message":"unauthorized access"}
'. Please check that the bucket, org and token are correct and that the token has the correct permissions set. Retrying in 60 seconds.
2021-10-05 16:36:48 ERROR (MainThread) [homeassistant] Error doing job: Task exception was never retrieved
Traceback (most recent call last):
  File "/usr/src/homeassistant/homeassistant/components/notify/__init__.py", line 327, in async_setup_platform
    await notify_service.async_setup(
AttributeError: 'bool' object has no attribute 'async_setup'
2021-10-05 16:36:48 ERROR (MainThread) [homeassistant] Error doing job: Task exception was never retrieved
Traceback (most recent call last):
  File "/usr/src/homeassistant/homeassistant/core.py", line 1439, in async_call
    raise ServiceNotFound(domain, service) from None
homeassistant.exceptions.ServiceNotFound: Unable to find service notify.mobile_app_miguel_mac_work
2021-10-05 16:36:49 ERROR (MainThread) [homeassistant] Error doing job: Task exception was never retrieved
Traceback (most recent call last):
  File "/usr/src/homeassistant/homeassistant/components/waze_travel_time/sensor.py", line 238, in first_update
    await self.hass.async_add_executor_job(self.update)
  File "/usr/local/lib/python3.9/concurrent/futures/thread.py", line 52, in run
    result = self.fn(*self.args, **self.kwargs)
  File "/usr/src/homeassistant/homeassistant/components/waze_travel_time/sensor.py", line 264, in update
    self._waze_data.update()
  File "/usr/src/homeassistant/homeassistant/components/waze_travel_time/sensor.py", line 320, in update
    routes = params.calc_all_routes_info(real_time=realtime)
  File "/usr/local/lib/python3.9/site-packages/WazeRouteCalculator/WazeRouteCalculator.py", line 203, in calc_all_routes_info
    results = {route['routeName']: self._add_up_route(route['results'], real_time=real_time, stop_at_bounds=stop_at_bounds) for route in routes}
  File "/usr/local/lib/python3.9/site-packages/WazeRouteCalculator/WazeRouteCalculator.py", line 203, in <dictcomp>
    results = {route['routeName']: self._add_up_route(route['results'], real_time=real_time, stop_at_bounds=stop_at_bounds) for route in routes}
TypeError: list indices must be integers or slices, not str
2021-10-05 16:36:49 ERROR (MainThread) [homeassistant] Error doing job: Task exception was never retrieved
Traceback (most recent call last):
  File "/usr/src/homeassistant/homeassistant/components/waze_travel_time/sensor.py", line 238, in first_update
    await self.hass.async_add_executor_job(self.update)
  File "/usr/local/lib/python3.9/concurrent/futures/thread.py", line 52, in run
    result = self.fn(*self.args, **self.kwargs)
  File "/usr/src/homeassistant/homeassistant/components/waze_travel_time/sensor.py", line 264, in update
    self._waze_data.update()
  File "/usr/src/homeassistant/homeassistant/components/waze_travel_time/sensor.py", line 320, in update
    routes = params.calc_all_routes_info(real_time=realtime)
  File "/usr/local/lib/python3.9/site-packages/WazeRouteCalculator/WazeRouteCalculator.py", line 203, in calc_all_routes_info
    results = {route['routeName']: self._add_up_route(route['results'], real_time=real_time, stop_at_bounds=stop_at_bounds) for route in routes}
  File "/usr/local/lib/python3.9/site-packages/WazeRouteCalculator/WazeRouteCalculator.py", line 203, in <dictcomp>
    results = {route['routeName']: self._add_up_route(route['results'], real_time=real_time, stop_at_bounds=stop_at_bounds) for route in routes}
TypeError: list indices must be integers or slices, not str
2021-10-05 16:36:55 ERROR (MainThread) [homeassistant] Error doing job: Task exception was never retrieved
Traceback (most recent call last):
  File "/usr/src/homeassistant/homeassistant/components/waze_travel_time/sensor.py", line 238, in first_update
    await self.hass.async_add_executor_job(self.update)
  File "/usr/local/lib/python3.9/concurrent/futures/thread.py", line 52, in run
    result = self.fn(*self.args, **self.kwargs)
  File "/usr/src/homeassistant/homeassistant/components/waze_travel_time/sensor.py", line 264, in update
    self._waze_data.update()
  File "/usr/src/homeassistant/homeassistant/components/waze_travel_time/sensor.py", line 320, in update
    routes = params.calc_all_routes_info(real_time=realtime)
  File "/usr/local/lib/python3.9/site-packages/WazeRouteCalculator/WazeRouteCalculator.py", line 203, in calc_all_routes_info
    results = {route['routeName']: self._add_up_route(route['results'], real_time=real_time, stop_at_bounds=stop_at_bounds) for route in routes}
  File "/usr/local/lib/python3.9/site-packages/WazeRouteCalculator/WazeRouteCalculator.py", line 203, in <dictcomp>
    results = {route['routeName']: self._add_up_route(route['results'], real_time=real_time, stop_at_bounds=stop_at_bounds) for route in routes}
TypeError: list indices must be integers or slices, not str
2021-10-05 16:37:01 ERROR (MainThread) [homeassistant] Error doing job: Task exception was never retrieved
Traceback (most recent call last):
  File "/usr/src/homeassistant/homeassistant/components/waze_travel_time/sensor.py", line 238, in first_update
    await self.hass.async_add_executor_job(self.update)
  File "/usr/local/lib/python3.9/concurrent/futures/thread.py", line 52, in run
    result = self.fn(*self.args, **self.kwargs)
  File "/usr/src/homeassistant/homeassistant/components/waze_travel_time/sensor.py", line 264, in update
    self._waze_data.update()
  File "/usr/src/homeassistant/homeassistant/components/waze_travel_time/sensor.py", line 320, in update
    routes = params.calc_all_routes_info(real_time=realtime)
  File "/usr/local/lib/python3.9/site-packages/WazeRouteCalculator/WazeRouteCalculator.py", line 203, in calc_all_routes_info
    results = {route['routeName']: self._add_up_route(route['results'], real_time=real_time, stop_at_bounds=stop_at_bounds) for route in routes}
  File "/usr/local/lib/python3.9/site-packages/WazeRouteCalculator/WazeRouteCalculator.py", line 203, in <dictcomp>
    results = {route['routeName']: self._add_up_route(route['results'], real_time=real_time, stop_at_bounds=stop_at_bounds) for route in routes}
TypeError: list indices must be integers or slices, not str
2021-10-05 16:37:47 ERROR (SyncWorker_4) [homeassistant.components.influxdb] InfluxDB bucket is not accessible due to '(401)
Reason: Unauthorized
HTTP response headers: HTTPHeaderDict({'Content-Type': 'application/json; charset=utf-8', 'X-Platform-Error-Code': 'unauthorized', 'Date': 'Tue, 05 Oct 2021 21:37:47 GMT', 'Content-Length': '55'})
HTTP response body: {"code":"unauthorized","message":"unauthorized access"}
'. Please check that the bucket, org and token are correct and that the token has the correct permissions set. Retrying in 60 seconds.
2021-10-05 16:37:52 WARNING (MainThread) [homeassistant.components.automation] Error evaluating condition in 'Front Door status notify':
In 'condition':
  In 'numeric_state':
    In 'numeric_state' condition: entity sensor.home_assistant_uptime state '2021-10-05T16:35:48.416916-05:00' cannot be processed as a number
2021-10-05 16:37:52 WARNING (MainThread) [homeassistant.components.automation] Error evaluating condition in 'Front Door status notify':
In 'condition':
  In 'numeric_state':
    In 'numeric_state' condition: entity sensor.home_assistant_uptime state '2021-10-05T16:35:48.416916-05:00' cannot be processed as a number
2021-10-05 16:37:52 WARNING (MainThread) [homeassistant.components.automation] Error evaluating condition in 'Front Door status notify':
In 'condition':
  In 'numeric_state':
    In 'numeric_state' condition: entity sensor.home_assistant_uptime state '2021-10-05T16:35:48.416916-05:00' cannot be processed as a number
2021-10-05 16:38:04 WARNING (MainThread) [homeassistant.components.uptime.sensor] The 'unit_of_measurement' option is deprecated, please remove it from your configuration
2021-10-05 16:38:04 ERROR (MainThread) [homeassistant] Error doing job: Task exception was never retrieved
Traceback (most recent call last):
  File "/usr/src/homeassistant/homeassistant/core.py", line 1439, in async_call
    raise ServiceNotFound(domain, service) from None
homeassistant.exceptions.ServiceNotFound: Unable to find service notify.mobile_app_miguel_mac_work
